Workbook

Sheet -> Threat Hunt Result

Sheet Result
A1: _time | B1: index | C1: sourcetype | D1: Source_IP | E1: Destination_IP | F1: Destination_Port | G1: action | H1: Tag_value | I1: Label | J1: Traffic (Outbound/Inbound/Unknown) | K1: Direction Mismatch: Outbound/Inbound Conflict | L1: Follow up action | M1: count | N1: Remark
A2: 2026-07-12T23:56:13.000+0800 | B2: soc_fortinet | C2: fgt_log fortigate_utm | D2: 172.22.100.186 172.22.100.187 172.22.103.184 172.22.99.186 172.22.99.187 192.168.202.31 | E2: 150.171.28.10 | F2: 443 80 | G2: accept allowed pass | H2: 專題-全球風險IP通報 | I2: 僵屍網絡 | J2: =VLOOKUP(E2,'Follow-up Action'!A:C, 3,FALSE) -> outbound | K2: No | L2: =VLOOKUP(E2,'Follow-up Action'!A:D,4,FALSE) -> Block | M2: 19187 | N2: Outbound traffic to external source from HKMA asset detected; No successful inbound traffic from external source
A3: 2026-07-12T23:59:58.000+0800 | B3: soc_fortinet | C3: fgt_log fortigate_utm | D3: 172.22.103.184 172.22.99.186 172.22.99.187 192.168.202.31 | E3: 104.16.80.73 | F3: 443 | G3: accept allowed pass | H3: 惡意事件(B) | I3: 掃描操作 | J3: =VLOOKUP(E3,'Follow-up Action'!A:C, 3,FALSE) -> inbound | K3: Yes | L3: Alert | M3: 15096 | N3: Outbound traffic to external source from HKMA asset detected; No successful inbound traffic from external source
A4: 2026-07-12T23:40:41.000+0800 | B4: soc_fortinet | C4: fgt_log | D4: 172.22.100.187 172.22.99.186 172.22.99.187 192.168.202.31 | E4: 104.16.79.73 | F4: 443 | G4: accept pass | H4: 惡意事件(B) | I4: 掃描操作 | J4: =VLOOKUP(E4,'Follow-up Action'!A:C, 3,FALSE) -> inbound | K4: Yes | L4: Alert | M4: 4465 | N4: Outbound HTTP Traffic via Port 80/443
A5: 2026-07-12T23:24:08.000+0800 | B5: soc_fortinet | C5: fgt_log | D5: 172.22.99.186 172.22.99.187 192.168.202.31 | E5: 155.102.175.140 | F5: 443 80 | G5: accept pass | H5: 惡意事件(B) | I5: 掃描操作 | J5: =VLOOKUP(E5,'Follow-up Action'!A:C, 3,FALSE) -> inbound | K5: Yes | L5: Alert | M5: 3893 | N5: Outbound HTTP Traffic via Port 80/443
A6: 2026-07-12T23:48:28.000+0800 | B6: soc_fortinet | C6: fgt_log | D6: 172.22.99.186 172.22.99.187 192.168.202.31 | E6: 155.102.175.145 | F6: 443 80 | G6: accept pass | H6: 惡意事件(B) | I6: 掃描操作 | J6: =VLOOKUP(E6,'Follow-up Action'!A:C, 3,FALSE) -> inbound | K6: Yes | L6: Alert | M6: 1824 | N6: Outbound HTTP Traffic via Port 80/443
A7: 2026-07-12T23:03:42.000+0800 | B7: soc_fortinet | C7: fgt_log fortigate_utm | D7: 172.22.99.186 172.22.99.187 192.168.202.31 | E7: 155.102.175.144 | F7: 443 80 | G7: accept allowed pass | H7: 惡意事件(B) | I7: 掃描操作 | J7: =VLOOKUP(E7,'Follow-up Action'!A:C, 3,FALSE) -> inbound | K7: Yes | L7: Alert | M7: 1649 | N7: Outbound traffic to external source from HKMA asset detected; No successful inbound traffic from external source
A8: 2026-07-12T23:22:34.000+0800 | B8: soc_fortinet | C8: fgt_log | D8: 172.22.99.186 172.22.99.187 192.168.202.31 | E8: 155.102.175.142 | F8: 443 80 | G8: accept pass | H8: 惡意事件(B) | I8: 掃描操作 | J8: =VLOOKUP(E8,'Follow-up Action'!A:C, 3,FALSE) -> inbound | K8: Yes | L8: Alert | M8: 1628 | N8: Outbound HTTP Traffic via Port 80/443
A9: 2026-07-12T23:46:19.000+0800 | B9: soc_fortinet | C9: fgt_log fortigate_utm | D9: 172.22.99.186 172.22.99.187 192.168.202.31 | E9: 155.102.175.141 | F9: 443 80 | G9: accept allowed pass | H9: 惡意事件(B) | I9: 掃描操作 | J9: =VLOOKUP(E9,'Follow-up Action'!A:C, 3,FALSE) -> inbound | K9: Yes | L9: Alert | M9: 1602 | N9: Outbound traffic to external source from HKMA asset detected; No successful inbound traffic from external source
A10: 2026-07-12T23:57:49.000+0800 | B10: soc_fortinet | C10: fgt_log | D10: 172.22.99.186 172.22.99.187 192.168.202.31 | E10: 155.102.175.143 | F10: 443 80 | G10: accept pass | H10: 惡意事件(B) | I10: 掃描操作 | J10: =VLOOKUP(E10,'Follow-up Action'!A:C, 3,FALSE) -> inbound | K10: Yes | L10: Alert | M10: 1530 | N10: Outbound HTTP Traffic via Port 80/443
A11: 2026-07-10T17:22:04.000+0800 | B11: soc_fortinet | C11: fgt_log | D11: 172.22.99.186 172.22.99.187 | E11: 157.185.135.95 | F11: 443 80 | G11: accept pass | H11: 惡意事件(B) | I11: 掃描操作 | J11: =VLOOKUP(E11,'Follow-up Action'!A:C, 3,FALSE) -> inbound | K11: Yes | L11: Alert | M11: 541 | N11: Outbound HTTP Traffic via Port 80/443
A12: 2026-07-12T23:58:58.000+0800 | B12: soc_fortinet | C12: fgt_log | D12: 216.244.66.243 | E12: 172.22.50.70 | F12: 443 80 | G12: pass | H12: 惡意事件(B) | I12: =VLOOKUP(D12,'Follow-up Action'!A:B,2,FALSE) -> "Exploit", "CyberAttack" | J12: =VLOOKUP(D12,'Follow-up Action'!A:C, 3,FALSE) -> inbound | K12: No | L12: =VLOOKUP(D12,'Follow-up Action'!A:D,4,FALSE) -> Block | M12: 532 | N12: Inbound scanning activity
A13: 2026-07-12T21:13:31.000+0800 | B13: soc_fortinet | C13: fgt_log | D13: 216.244.66.249 | E13: 172.22.50.70 | F13: 443 80 | G13: pass | H13: 惡意事件(B) | I13: =VLOOKUP(D13,'Follow-up Action'!A:B,2,FALSE) -> "Exploit", "CyberAttack" | J13: =VLOOKUP(D13,'Follow-up Action'!A:C, 3,FALSE) -> inbound | K13: No | L13: =VLOOKUP(D13,'Follow-up Action'!A:D,4,FALSE) -> Block | M13: 517 | N13: Inbound scanning activity
A14: 2026-07-12T01:02:06.000+0800 | B14: soc_fortinet | C14: fgt_log | D14: 172.22.99.186 172.22.99.187 | E14: 153.43.128.22 | F14: 443 80 | G14: accept pass | H14: 惡意事件(B) | I14: 掃描操作 | J14: =VLOOKUP(E14,'Follow-up Action'!A:C, 3,FALSE) -> inbound | K14: Yes | L14: Alert | M14: 485 | N14: Outbound HTTP Traffic via Port 80/443
A15: 2026-07-12T22:03:40.000+0800 | B15: soc_fortinet | C15: fgt_log | D15: 216.244.66.200 | E15: 172.22.50.70 | F15: 443 80 | G15: pass | H15: 惡意事件(B) | I15: =VLOOKUP(D15,'Follow-up Action'!A:B,2,FALSE) -> "Exploit", "CyberAttack" | J15: =VLOOKUP(D15,'Follow-up Action'!A:C, 3,FALSE) -> inbound | K15: No | L15: =VLOOKUP(D15,'Follow-up Action'!A:D,4,FALSE) -> Block | M15: 358 | N15: Inbound scanning activity
A16: 2026-07-10T16:16:50.000+0800 | B16: soc_fortinet | C16: fgt_log | D16: 138.199.62.10 | E16: 172.22.99.20 | F16: 443 | G16: pass | H16: 惡意事件(A) | I16: =VLOOKUP(D16,'Follow-up Action'!A:B,2,FALSE) -> 無 | J16: =VLOOKUP(D16,'Follow-up Action'!A:C, 3,FALSE) -> unknown | K16: No | L16: =VLOOKUP(D16,'Follow-up Action'!A:D,4,FALSE) -> Alert | M16: 243 | N16: Inbound scanning activity
A17: 2026-07-10T17:25:46.000+0800 | B17: soc_fortinet | C17: fgt_log | D17: 172.22.99.186 172.22.99.187 | E17: 157.185.135.194 | F17: 443 | G17: accept pass | H17: 惡意事件(B) | I17: 掃描操作 | J17: =VLOOKUP(E17,'Follow-up Action'!A:C, 3,FALSE) -> inbound | K17: Yes | L17: Alert | M17: 243 | N17: Outbound HTTP Traffic via Port 80/443
A18: 2026-07-12T23:45:09.000+0800 | B18: soc_fortinet | C18: fgt_log fortigate_utm | D18: 141.98.83.48 | E18: 172.22.99.90 | F18: 443 80 | G18: allowed pass | H18: DDoS攻擊 | I18: =VLOOKUP(D18,'Follow-up Action'!A:B,2,FALSE) -> DDoS | J18: =VLOOKUP(D18,'Follow-up Action'!A:C, 3,FALSE) -> inbound | K18: No | L18: =VLOOKUP(D18,'Follow-up Action'!A:D,4,FALSE) -> Block | M18: 142 | N18: Inbound traffic to HKMA assets (172.22.99.90) from external source detected; No successful outbound traffic from 172.22.99.90
A19: 2026-07-10T16:21:27.000+0800 | B19: soc_fortinet | C19: fgt_log | D19: 138.199.62.10 | E19: 121.101.172.38 | F19: 53 | G19: accept | H19: 惡意事件(A) | I19: =VLOOKUP(D19,'Follow-up Action'!A:B,2,FALSE) -> 無 | J19: =VLOOKUP(D19,'Follow-up Action'!A:C, 3,FALSE) -> unknown | K19: No | L19: =VLOOKUP(D19,'Follow-up Action'!A:D,4,FALSE) -> Alert | M19: 119 | N19: Inbound DNS traffic to Internet-facing devices via Port 53
A20: 2026-07-12T23:46:33.000+0800 | B20: soc_fortinet | C20: fgt_log fortigate_utm | D20: 141.98.83.48 | E20: 172.22.99.15 | F20: 443 80 | G20: allowed pass | H20: DDoS攻擊 | I20: =VLOOKUP(D20,'Follow-up Action'!A:B,2,FALSE) -> DDoS | J20: =VLOOKUP(D20,'Follow-up Action'!A:C, 3,FALSE) -> inbound | K20: No | L20: =VLOOKUP(D20,'Follow-up Action'!A:D,4,FALSE) -> Block | M20: 111 | N20: Inbound traffic to HKMA assets (172.22.99.15) from external source detected; No successful outbound traffic from 172.22.99.15
A21: 2026-07-12T23:47:12.000+0800 | B21: soc_fortinet | C21: fgt_log fortigate_utm | D21: 141.98.83.48 | E21: 172.22.99.91 | F21: 80 | G21: allowed pass | H21: DDoS攻擊 | I21: =VLOOKUP(D21,'Follow-up Action'!A:B,2,FALSE) -> DDoS | J21: =VLOOKUP(D21,'Follow-up Action'!A:C, 3,FALSE) -> inbound | K21: No | L21: =VLOOKUP(D21,'Follow-up Action'!A:D,4,FALSE) -> Block | M21: 101 | N21: Inbound traffic to HKMA assets (172.22.99.91) from external source detected; No successful outbound traffic from 172.22.99.91
A22: 2026-07-12T15:11:04.000+0800 | B22: soc_fortinet | C22: fgt_log | D22: 172.216.245.31 | E22: 121.101.168.51 | F22: 53 | G22: accept | H22: 惡意事件(B) | I22: =VLOOKUP(D22,'Follow-up Action'!A:B,2,FALSE) -> "Exploit", "CyberAttack" | J22: =VLOOKUP(D22,'Follow-up Action'!A:C, 3,FALSE) -> inbound | K22: No | L22: =VLOOKUP(D22,'Follow-up Action'!A:D,4,FALSE) -> Block | M22: 93 | N22: Inbound DNS traffic to Internet-facing devices via Port 53
A23: 2026-07-10T16:19:50.000+0800 | B23: soc_fortinet | C23: fgt_log | D23: 138.199.62.10 | E23: 121.101.168.51 | F23: 53 | G23: accept | H23: 惡意事件(A) | I23: =VLOOKUP(D23,'Follow-up Action'!A:B,2,FALSE) -> 無 | J23: =VLOOKUP(D23,'Follow-up Action'!A:C, 3,FALSE) -> unknown | K23: No | L23: =VLOOKUP(D23,'Follow-up Action'!A:D,4,FALSE) -> Alert | M23: 92 | N23: Inbound DNS traffic to Internet-facing devices via Port 53
A24: 2026-07-11T17:46:10.000+0800 | B24: soc_fortinet | C24: fgt_log | D24: 172.216.245.31 | E24: 121.101.172.38 | F24: 53 | G24: accept | H24: 惡意事件(B) | I24: =VLOOKUP(D24,'Follow-up Action'!A:B,2,FALSE) -> "Exploit", "CyberAttack" | J24: =VLOOKUP(D24,'Follow-up Action'!A:C, 3,FALSE) -> inbound | K24: No | L24: =VLOOKUP(D24,'Follow-up Action'!A:D,4,FALSE) -> Block | M24: 78 | N24: Inbound DNS traffic to Internet-facing devices via Port 53
A25: 2026-07-06T23:05:47.000+0800 | B25: soc_fortinet | C25: fgt_log fortigate_utm | D25: 141.98.83.48 | E25: 172.22.99.20 | F25: 443 | G25: allowed pass | H25: DDoS攻擊 | I25: =VLOOKUP(D25,'Follow-up Action'!A:B,2,FALSE) -> DDoS | J25: =VLOOKUP(D25,'Follow-up Action'!A:C, 3,FALSE) -> inbound | K25: No | L25: =VLOOKUP(D25,'Follow-up Action'!A:D,4,FALSE) -> Block | M25: 72 | N25: Inbound traffic to HKMA assets (172.22.99.20) from external source detected; No successful outbound traffic from 172.22.99.20
A26: 2026-07-12T02:51:23.000+0800 | B26: soc_fortinet | C26: fgt_log | D26: 47.253.5.130 | E26: 172.22.100.74 | F26: 443 | G26: pass | H26: 惡意事件(B) | I26: =VLOOKUP(D26,'Follow-up Action'!A:B,2,FALSE) -> "Exploit", "CyberAttack" | J26: =VLOOKUP(D26,'Follow-up Action'!A:C, 3,FALSE) -> inbound | K26: No | L26: =VLOOKUP(D26,'Follow-up Action'!A:D,4,FALSE) -> Block | M26: 70 | N26: Inbound scanning activity
A27: 2026-07-11T19:29:14.000+0800 | B27: soc_fortinet | C27: fgt_log | D27: 216.244.66.243 | E27: 172.22.51.70 | F27: 443 80 | G27: pass | H27: 惡意事件(B) | I27: =VLOOKUP(D27,'Follow-up Action'!A:B,2,FALSE) -> "Exploit", "CyberAttack" | J27: =VLOOKUP(D27,'Follow-up Action'!A:C, 3,FALSE) -> inbound | K27: No | L27: =VLOOKUP(D27,'Follow-up Action'!A:D,4,FALSE) -> Block | M27: 69 | N27: Inbound scanning activity
A28: 2026-07-06T23:06:36.000+0800 | B28: soc_fortinet | C28: fgt_log fortigate_utm | D28: 141.98.83.48 | E28: 172.22.99.181 | F28: 443 | G28: allowed pass | H28: DDoS攻擊 | I28: =VLOOKUP(D28,'Follow-up Action'!A:B,2,FALSE) -> DDoS | J28: =VLOOKUP(D28,'Follow-up Action'!A:C, 3,FALSE) -> inbound | K28: No | L28: =VLOOKUP(D28,'Follow-up Action'!A:D,4,FALSE) -> Block | M28: 68 | N28: Inbound traffic to HKMA assets (172.22.99.181) from external source detected; No successful outbound traffic from 172.22.99.181
A29: 2026-07-06T22:46:15.000+0800 | B29: soc_fortinet | C29: fgt_log fortigate_utm | D29: 141.98.83.48 | E29: 172.22.99.183 | F29: 443 | G29: allowed pass | H29: DDoS攻擊 | I29: =VLOOKUP(D29,'Follow-up Action'!A:B,2,FALSE) -> DDoS | J29: =VLOOKUP(D29,'Follow-up Action'!A:C, 3,FALSE) -> inbound | K29: No | L29: =VLOOKUP(D29,'Follow-up Action'!A:D,4,FALSE) -> Block | M29: 66 | N29: Inbound traffic to HKMA assets (172.22.99.183) from external source detected; No successful outbound traffic from 172.22.99.183
A30: 2026-07-10T12:10:44.000+0800 | B30: soc_fortinet | C30: fgt_log | D30: 172.22.99.186 172.22.99.187 | E30: 123.59.186.141 | F30: 443 | G30: pass | H30: DDoS攻擊 | I30: =VLOOKUP(E30,'Follow-up Action'!A:B,2,FALSE) -> DDoS | J30: Inbound | K30: Yes | L30: =VLOOKUP(E30,'Follow-up Action'!A:D,4,FALSE) -> Alert | M30: 63 | N30: Outbound HTTP Traffic via Port 80/443
A31: 2026-07-09T22:09:08.000+0800 | B31: soc_fortinet | C31: fgt_log | D31: 47.253.5.130 | E31: 172.22.99.76 | F31: 443 | G31: pass | H31: 惡意事件(B) | I31: =VLOOKUP(D31,'Follow-up Action'!A:B,2,FALSE) -> "Exploit", "CyberAttack" | J31: =VLOOKUP(D31,'Follow-up Action'!A:C, 3,FALSE) -> inbound | K31: No | L31: =VLOOKUP(D31,'Follow-up Action'!A:D,4,FALSE) -> Block | M31: 62 | N31: Inbound scanning activity
A32: 2026-07-11T05:25:45.000+0800 | B32: soc_fortinet | C32: fgt_log | D32: 216.57.110.81 | E32: 172.22.99.15 | F32: 443 | G32: pass | H32: 惡意事件(B) | I32: =VLOOKUP(D32,'Follow-up Action'!A:B,2,FALSE) -> "Exploit", "CyberAttack" | J32: =VLOOKUP(D32,'Follow-up Action'!A:C, 3,FALSE) -> inbound | K32: No | L32: =VLOOKUP(D32,'Follow-up Action'!A:D,4,FALSE) -> Block | M32: 61 | N32: Inbound scanning activity
A33: 2026-07-12T20:28:55.000+0800 | B33: soc_fortinet | C33: fgt_log | D33: 47.251.53.147 | E33: 172.22.100.23 | F33: 443 | G33: pass | H33: 惡意事件(B) | I33: =VLOOKUP(D33,'Follow-up Action'!A:B,2,FALSE) -> "Exploit", "CyberAttack" | J33: =VLOOKUP(D33,'Follow-up Action'!A:C, 3,FALSE) -> inbound | K33: No | L33: =VLOOKUP(D33,'Follow-up Action'!A:D,4,FALSE) -> Block | M33: 56 | N33: Inbound scanning activity
A34: 2026-07-09T15:59:24.000+0800 | B34: soc_fortinet | C34: fgt_log | D34: 172.22.100.187 172.22.99.186 172.22.99.187 | E34: 23.33.92.22 | F34: 443 80 | G34: accept pass | H34: 惡意事件(A) | I34: 無 | J34: =VLOOKUP(E34,'Follow-up Action'!A:C, 3,FALSE) -> unknown | K34: No | L34: =VLOOKUP(E34,'Follow-up Action'!A:D,4,FALSE) -> Alert | M34: 52 | N34: Outbound HTTP Traffic via Port 80/443
A35: 2026-07-12T23:36:13.000+0800 | B35: soc_fortinet | C35: fgt_log | D35: 66.249.68.164 | E35: 172.22.50.70 | F35: 443 80 | G35: pass | H35: 惡意事件(B) | I35: =VLOOKUP(D35,'Follow-up Action'!A:B,2,FALSE) -> "Exploit", "CyberAttack" | J35: =VLOOKUP(D35,'Follow-up Action'!A:C, 3,FALSE) -> inbound | K35: No | L35: =VLOOKUP(D35,'Follow-up Action'!A:D,4,FALSE) -> Block | M35: 50 | N35: Inbound scanning activity
A36: 2026-07-12T23:36:14.000+0800 | B36: soc_fortinet | C36: fgt_log | D36: 66.249.68.165 | E36: 172.22.50.70 | F36: 443 80 | G36: pass | H36: 惡意事件(B) | I36: =VLOOKUP(D36,'Follow-up Action'!A:B,2,FALSE) -> "Exploit", "CyberAttack" | J36: =VLOOKUP(D36,'Follow-up Action'!A:C, 3,FALSE) -> inbound | K36: No | L36: =VLOOKUP(D36,'Follow-up Action'!A:D,4,FALSE) -> Block | M36: 50 | N36: Inbound scanning activity
A37: 2026-07-11T17:43:08.000+0800 | B37: soc_fortinet | C37: fgt_log | D37: 172.216.245.31 | E37: 172.22.99.20 | F37: 443 | G37: pass | H37: 惡意事件(B) | I37: =VLOOKUP(D37,'Follow-up Action'!A:B,2,FALSE) -> "Exploit", "CyberAttack" | J37: =VLOOKUP(D37,'Follow-up Action'!A:C, 3,FALSE) -> inbound | K37: No | L37: =VLOOKUP(D37,'Follow-up Action'!A:D,4,FALSE) -> Block | M37: 45 | N37: Inbound scanning activity
A38: 2026-07-10T05:04:12.000+0800 | B38: soc_fortinet | C38: fgt_log | D38: 47.253.5.130 | E38: 172.22.100.181 | F38: 443 | G38: pass | H38: 惡意事件(B) | I38: =VLOOKUP(D38,'Follow-up Action'!A:B,2,FALSE) -> "Exploit", "CyberAttack" | J38: =VLOOKUP(D38,'Follow-up Action'!A:C, 3,FALSE) -> inbound | K38: No | L38: =VLOOKUP(D38,'Follow-up Action'!A:D,4,FALSE) -> Block | M38: 45 | N38: Inbound scanning activity
A39: 2026-07-11T06:56:05.000+0800 | B39: soc_fortinet | C39: fgt_log | D39: 86.54.31.38 | E39: 172.22.99.178 | F39: 443 | G39: pass | H39: 惡意事件(B) | I39: =VLOOKUP(D39,'Follow-up Action'!A:B,2,FALSE) -> "Exploit", "CyberAttack" | J39: =VLOOKUP(D39,'Follow-up Action'!A:C, 3,FALSE) -> inbound | K39: No | L39: =VLOOKUP(D39,'Follow-up Action'!A:D,4,FALSE) -> Block | M39: 45 | N39: Inbound scanning activity
A40: 2026-07-12T16:55:28.000+0800 | B40: soc_fortinet | C40: fgt_log | D40: 144.126.215.119 | E40: 172.22.100.76 | F40: 443 | G40: pass | H40: 惡意事件(B) | I40: =VLOOKUP(D40,'Follow-up Action'!A:B,2,FALSE) -> "Exploit", "CyberAttack" | J40: =VLOOKUP(D40,'Follow-up Action'!A:C, 3,FALSE) -> inbound | K40: No | L40: =VLOOKUP(D40,'Follow-up Action'!A:D,4,FALSE) -> Block | M40: 44 | N40: Inbound scanning activity
...

Sheet Follow-up Action
A1: IOC | B1: Label | C1: Traffic (Outbound/Inbound/Unknown) | D1: Follow up action | F1: Label | G1: Traffic (Outbound/Inbound/Unknown) | I1: Classification | J1: Follow up action
A2: 103.40.79.139 | B2: 無 | C2: {=IFERROR( IF(SUMPRODUCT((LEN(B2)-LEN(SUBSTITUTE(B2,$F$2:$F$300,"")))*(($G$2:$G$300)="outbound"))>0,"outbound", IF(SUMPRODUCT((LEN(B2)-LEN(SUBSTITUTE(B2,$F$2:$F$300,"")))*(($G$2:$G$300)="inbound"))>0,"inbound","unknown")), "unknown" )} -> unknown | D2: =VLOOKUP(C2,$I$2:$J$5,2,FALSE) -> Alert | F2: 釣魚網站 | G2: outbound | I2: Inbound | J2: Block
A3: 14.29.236.229 | B3: APT組織：OceanLotus | C3: {=IFERROR( IF(SUMPRODUCT((LEN(B3)-LEN(SUBSTITUTE(B3,$F$2:$F$300,"")))*(($G$2:$G$300)="outbound"))>0,"outbound", IF(SUMPRODUCT((LEN(B3)-LEN(SUBSTITUTE(B3,$F$2:$F$300,"")))*(($G$2:$G$300)="inbound"))>0,"inbound","unknown")), "unknown" )} -> unknown | D3: =VLOOKUP(C3,$I$2:$J$5,2,FALSE) -> Alert | F3: Websafe.Phishing | G3: outbound | I3: Outbound | J3: Block
A4: 103.57.248.171 | B4: 無 | C4: {=IFERROR( IF(SUMPRODUCT((LEN(B4)-LEN(SUBSTITUTE(B4,$F$2:$F$300,"")))*(($G$2:$G$300)="outbound"))>0,"outbound", IF(SUMPRODUCT((LEN(B4)-LEN(SUBSTITUTE(B4,$F$2:$F$300,"")))*(($G$2:$G$300)="inbound"))>0,"inbound","unknown")), "unknown" )} -> unknown | D4: =VLOOKUP(C4,$I$2:$J$5,2,FALSE) -> Alert | F4: Phishing | G4: outbound | I4: Unknown | J4: Alert
A5: 138.199.62.10 | B5: 無 | C5: {=IFERROR( IF(SUMPRODUCT((LEN(B5)-LEN(SUBSTITUTE(B5,$F$2:$F$300,"")))*(($G$2:$G$300)="outbound"))>0,"outbound", IF(SUMPRODUCT((LEN(B5)-LEN(SUBSTITUTE(B5,$F$2:$F$300,"")))*(($G$2:$G$300)="inbound"))>0,"inbound","unknown")), "unknown" )} -> unknown | D5: =VLOOKUP(C5,$I$2:$J$5,2,FALSE) -> Alert | F5: Silver fox | G5: unknown | I5: Direction Mismatch: Outbound/Inbound Conflict | J5: Alert
A6: 118.99.2.23 | B6: 無 | C6: {=IFERROR( IF(SUMPRODUCT((LEN(B6)-LEN(SUBSTITUTE(B6,$F$2:$F$300,"")))*(($G$2:$G$300)="outbound"))>0,"outbound", IF(SUMPRODUCT((LEN(B6)-LEN(SUBSTITUTE(B6,$F$2:$F$300,"")))*(($G$2:$G$300)="inbound"))>0,"inbound","unknown")), "unknown" )} -> unknown | D6: =VLOOKUP(C6,$I$2:$J$5,2,FALSE) -> Alert | F6: OceanLotus | G6: unknown
A7: 149.40.54.75 | B7: 無 | C7: {=IFERROR( IF(SUMPRODUCT((LEN(B7)-LEN(SUBSTITUTE(B7,$F$2:$F$300,"")))*(($G$2:$G$300)="outbound"))>0,"outbound", IF(SUMPRODUCT((LEN(B7)-LEN(SUBSTITUTE(B7,$F$2:$F$300,"")))*(($G$2:$G$300)="inbound"))>0,"inbound","unknown")), "unknown" )} -> unknown | D7: =VLOOKUP(C7,$I$2:$J$5,2,FALSE) -> Alert | F7: Generic Trojan | G7: unknown
A8: 185.225.234.192 | B8: 無 | C8: {=IFERROR( IF(SUMPRODUCT((LEN(B8)-LEN(SUBSTITUTE(B8,$F$2:$F$300,"")))*(($G$2:$G$300)="outbound"))>0,"outbound", IF(SUMPRODUCT((LEN(B8)-LEN(SUBSTITUTE(B8,$F$2:$F$300,"")))*(($G$2:$G$300)="inbound"))>0,"inbound","unknown")), "unknown" )} -> unknown | D8: =VLOOKUP(C8,$I$2:$J$5,2,FALSE) -> Alert | F8: BlackMarket | G8: unknown
A9: 185.225.234.62 | B9: 無 | C9: {=IFERROR( IF(SUMPRODUCT((LEN(B9)-LEN(SUBSTITUTE(B9,$F$2:$F$300,"")))*(($G$2:$G$300)="outbound"))>0,"outbound", IF(SUMPRODUCT((LEN(B9)-LEN(SUBSTITUTE(B9,$F$2:$F$300,"")))*(($G$2:$G$300)="inbound"))>0,"inbound","unknown")), "unknown" )} -> unknown | D9: =VLOOKUP(C9,$I$2:$J$5,2,FALSE) -> Alert | F9: Gh0st | G9: unknown
A10: 156.146.45.194 | B10: 無 | C10: {=IFERROR( IF(SUMPRODUCT((LEN(B10)-LEN(SUBSTITUTE(B10,$F$2:$F$300,"")))*(($G$2:$G$300)="outbound"))>0,"outbound", IF(SUMPRODUCT((LEN(B10)-LEN(SUBSTITUTE(B10,$F$2:$F$300,"")))*(($G$2:$G$300)="inbound"))>0,"inbound","unknown")), "unknown" )} -> unknown | D10: =VLOOKUP(C10,$I$2:$J$5,2,FALSE) -> Alert | F10: SilverFox | G10: unknown
A11: 185.225.234.144 | B11: 無 | C11: {=IFERROR( IF(SUMPRODUCT((LEN(B11)-LEN(SUBSTITUTE(B11,$F$2:$F$300,"")))*(($G$2:$G$300)="outbound"))>0,"outbound", IF(SUMPRODUCT((LEN(B11)-LEN(SUBSTITUTE(B11,$F$2:$F$300,"")))*(($G$2:$G$300)="inbound"))>0,"inbound","unknown")), "unknown" )} -> unknown | D11: =VLOOKUP(C11,$I$2:$J$5,2,FALSE) -> Alert | F11: Botnet | G11: outbound
A12: 38.180.150.40 | B12: APT組織：OceanLotus | C12: {=IFERROR( IF(SUMPRODUCT((LEN(B12)-LEN(SUBSTITUTE(B12,$F$2:$F$300,"")))*(($G$2:$G$300)="outbound"))>0,"outbound", IF(SUMPRODUCT((LEN(B12)-LEN(SUBSTITUTE(B12,$F$2:$F$300,"")))*(($G$2:$G$300)="inbound"))>0,"inbound","unknown")), "unknown" )} -> unknown | D12: =VLOOKUP(C12,$I$2:$J$5,2,FALSE) -> Alert | F12: CnC | G12: outbound
A13: 183.87.124.189 | B13: 無 | C13: {=IFERROR( IF(SUMPRODUCT((LEN(B13)-LEN(SUBSTITUTE(B13,$F$2:$F$300,"")))*(($G$2:$G$300)="outbound"))>0,"outbound", IF(SUMPRODUCT((LEN(B13)-LEN(SUBSTITUTE(B13,$F$2:$F$300,"")))*(($G$2:$G$300)="inbound"))>0,"inbound","unknown")), "unknown" )} -> unknown | D13: =VLOOKUP(C13,$I$2:$J$5,2,FALSE) -> Alert | F13: Scanner | G13: inbound
A14: 192.166.244.113 | B14: 無 | C14: {=IFERROR( IF(SUMPRODUCT((LEN(B14)-LEN(SUBSTITUTE(B14,$F$2:$F$300,"")))*(($G$2:$G$300)="outbound"))>0,"outbound", IF(SUMPRODUCT((LEN(B14)-LEN(SUBSTITUTE(B14,$F$2:$F$300,"")))*(($G$2:$G$300)="inbound"))>0,"inbound","unknown")), "unknown" )} -> unknown | D14: =VLOOKUP(C14,$I$2:$J$5,2,FALSE) -> Alert | F14: CyberAttack | G14: unknown
A15: 192.166.244.79 | B15: 無 | C15: {=IFERROR( IF(SUMPRODUCT((LEN(B15)-LEN(SUBSTITUTE(B15,$F$2:$F$300,"")))*(($G$2:$G$300)="outbound"))>0,"outbound", IF(SUMPRODUCT((LEN(B15)-LEN(SUBSTITUTE(B15,$F$2:$F$300,"")))*(($G$2:$G$300)="inbound"))>0,"inbound","unknown")), "unknown" )} -> unknown | D15: =VLOOKUP(C15,$I$2:$J$5,2,FALSE) -> Alert | F15: Spam | G15: inbound
A16: 203.168.241.141 | B16: 無 | C16: {=IFERROR( IF(SUMPRODUCT((LEN(B16)-LEN(SUBSTITUTE(B16,$F$2:$F$300,"")))*(($G$2:$G$300)="outbound"))>0,"outbound", IF(SUMPRODUCT((LEN(B16)-LEN(SUBSTITUTE(B16,$F$2:$F$300,"")))*(($G$2:$G$300)="inbound"))>0,"inbound","unknown")), "unknown" )} -> unknown | D16: =VLOOKUP(C16,$I$2:$J$5,2,FALSE) -> Alert | F16: BruteForcer | G16: inbound
A17: 43.249.51.79 | B17: 無 | C17: {=IFERROR( IF(SUMPRODUCT((LEN(B17)-LEN(SUBSTITUTE(B17,$F$2:$F$300,"")))*(($G$2:$G$300)="outbound"))>0,"outbound", IF(SUMPRODUCT((LEN(B17)-LEN(SUBSTITUTE(B17,$F$2:$F$300,"")))*(($G$2:$G$300)="inbound"))>0,"inbound","unknown")), "unknown" )} -> unknown | D17: =VLOOKUP(C17,$I$2:$J$5,2,FALSE) -> Alert | F17: Asyncrat | G17: unknown
... A146: 154.23.176.76 | B146: "CnC" | C146: {=IFERROR( IF(SUMPRODUCT((LEN(B146)-LEN(SUBSTITUTE(B146,$F$2:$F$300,"")))*(($G$2:$G$300)="outbound"))>0,"outbound", IF(SUMPRODUCT((LEN(B146)-LEN(SUBSTITUTE(B146,$F$2:$F$300,"")))*(($G$2:$G$300)="inbound"))>0,"inbound","unknown")), "unknown" )} -> outbound | D146: =VLOOKUP(C146,$I$2:$J$5,2,FALSE) -> Block | F146: 無 | G146: unknown
A147: 45.145.228.152 | B147: "Cobaltstrike", "CyberAttack", "CnC" | C147: {=IFERROR( IF(SUMPRODUCT((LEN(B147)-LEN(SUBSTITUTE(B147,$F$2:$F$300,"")))*(($G$2:$G$300)="outbound"))>0,"outbound", IF(SUMPRODUCT((LEN(B147)-LEN(SUBSTITUTE(B147,$F$2:$F$300,"")))*(($G$2:$G$300)="inbound"))>0,"inbound","unknown")), "unknown" )} -> outbound | D147: =VLOOKUP(C147,$I$2:$J$5,2,FALSE) -> Block
A148: 152.32.175.104 | B148: "Exploit", "Scanner" | C148: {=IFERROR( IF(SUMPRODUCT((LEN(B148)-LEN(SUBSTITUTE(B148,$F$2:$F$300,"")))*(($G$2:$G$300)="outbound"))>0,"outbound", IF(SUMPRODUCT((LEN(B148)-LEN(SUBSTITUTE(B148,$F$2:$F$300,"")))*(($G$2:$G$300)="inbound"))>0,"inbound","unknown")), "unknown" )} -> inbound | D148: =VLOOKUP(C148,$I$2:$J$5,2,FALSE) -> Block
A149: 8.218.44.185 | B149: "GoldenEye", "SilverFox" | C149: {=IFERROR( IF(SUMPRODUCT((LEN(B149)-LEN(SUBSTITUTE(B149,$F$2:$F$300,"")))*(($G$2:$G$300)="outbound"))>0,"outbound", IF(SUMPRODUCT((LEN(B149)-LEN(SUBSTITUTE(B149,$F$2:$F$300,"")))*(($G$2:$G$300)="inbound"))>0,"inbound","unknown")), "unknown" )} -> unknown | D149: =VLOOKUP(C149,$I$2:$J$5,2,FALSE) -> Alert
A150: 165.154.20.228 | B150: "Exploit", "Scanner" | C150: {=IFERROR( IF(SUMPRODUCT((LEN(B150)-LEN(SUBSTITUTE(B150,$F$2:$F$300,"")))*(($G$2:$G$300)="outbound"))>0,"outbound", IF(SUMPRODUCT((LEN(B150)-LEN(SUBSTITUTE(B150,$F$2:$F$300,"")))*(($G$2:$G$300)="inbound"))>0,"inbound","unknown")), "unknown" )} -> inbound | D150: =VLOOKUP(C150,$I$2:$J$5,2,FALSE) -> Block
A151: 36.255.220.195 | B151: "Exploit", "Scanner" | C151: {=IFERROR( IF(SUMPRODUCT((LEN(B151)-LEN(SUBSTITUTE(B151,$F$2:$F$300,"")))*(($G$2:$G$300)="outbound"))>0,"outbound", IF(SUMPRODUCT((LEN(B151)-LEN(SUBSTITUTE(B151,$F$2:$F$300,"")))*(($G$2:$G$300)="inbound"))>0,"inbound","unknown")), "unknown" )} -> inbound | D151: =VLOOKUP(C151,$I$2:$J$5,2,FALSE) -> Block
A152: 152.32.226.205 | B152: "Exploit", "Scanner" | C152: {=IFERROR( IF(SUMPRODUCT((LEN(B152)-LEN(SUBSTITUTE(B152,$F$2:$F$300,"")))*(($G$2:$G$300)="outbound"))>0,"outbound", IF(SUMPRODUCT((LEN(B152)-LEN(SUBSTITUTE(B152,$F$2:$F$300,"")))*(($G$2:$G$300)="inbound"))>0,"inbound","unknown")), "unknown" )} -> inbound | D152: =VLOOKUP(C152,$I$2:$J$5,2,FALSE) -> Block
A153: 47.238.121.28 | B153: "Exploit", "Scanner" | C153: {=IFERROR( IF(SUMPRODUCT((LEN(B153)-LEN(SUBSTITUTE(B153,$F$2:$F$300,"")))*(($G$2:$G$300)="outbound"))>0,"outbound", IF(SUMPRODUCT((LEN(B153)-LEN(SUBSTITUTE(B153,$F$2:$F$300,"")))*(($G$2:$G$300)="inbound"))>0,"inbound","unknown")), "unknown" )} -> inbound | D153: =VLOOKUP(C153,$I$2:$J$5,2,FALSE) -> Block
A154: 165.154.42.180 | B154: "Exploit", "Scanner" | C154: {=IFERROR( IF(SUMPRODUCT((LEN(B154)-LEN(SUBSTITUTE(B154,$F$2:$F$300,"")))*(($G$2:$G$300)="outbound"))>0,"outbound", IF(SUMPRODUCT((LEN(B154)-LEN(SUBSTITUTE(B154,$F$2:$F$300,"")))*(($G$2:$G$300)="inbound"))>0,"inbound","unknown")), "unknown" )} -> inbound | D154: =VLOOKUP(C154,$I$2:$J$5,2,FALSE) -> Block
A155: 152.32.186.194 | B155: "Exploit", "Scanner" | C155: {=IFERROR( IF(SUMPRODUCT((LEN(B155)-LEN(SUBSTITUTE(B155,$F$2:$F$300,"")))*(($G$2:$G$300)="outbound"))>0,"outbound", IF(SUMPRODUCT((LEN(B155)-LEN(SUBSTITUTE(B155,$F$2:$F$300,"")))*(($G$2:$G$300)="inbound"))>0,"inbound","unknown")), "unknown" )} -> inbound | D155: =VLOOKUP(C155,$I$2:$J$5,2,FALSE) -> Block
A156: 152.32.192.176 | B156: "Exploit", "BruteForcer", "Scanner" | C156: {=IFERROR( IF(SUMPRODUCT((LEN(B156)-LEN(SUBSTITUTE(B156,$F$2:$F$300,"")))*(($G$2:$G$300)="outbound"))>0,"outbound", IF(SUMPRODUCT((LEN(B156)-LEN(SUBSTITUTE(B156,$F$2:$F$300,"")))*(($G$2:$G$300)="inbound"))>0,"inbound","unknown")), "unknown" )} -> inbound | D156: =VLOOKUP(C156,$I$2:$J$5,2,FALSE) -> Block
A157: 36.255.223.90 | B157: "Exploit", "Scanner" | C157: {=IFERROR( IF(SUMPRODUCT((LEN(B157)-LEN(SUBSTITUTE(B157,$F$2:$F$300,"")))*(($G$2:$G$300)="outbound"))>0,"outbound", IF(SUMPRODUCT((LEN(B157)-LEN(SUBSTITUTE(B157,$F$2:$F$300,"")))*(($G$2:$G$300)="inbound"))>0,"inbound","unknown")), "unknown" )} -> inbound | D157: =VLOOKUP(C157,$I$2:$J$5,2,FALSE) -> Block
A158: 58.152.25.253 | B158: "Exploit", "BruteForcer", "Scanner" | C158: {=IFERROR( IF(SUMPRODUCT((LEN(B158)-LEN(SUBSTITUTE(B158,$F$2:$F$300,"")))*(($G$2:$G$300)="outbound"))>0,"outbound", IF(SUMPRODUCT((LEN(B158)-LEN(SUBSTITUTE(B158,$F$2:$F$300,"")))*(($G$2:$G$300)="inbound"))>0,"inbound","unknown")), "unknown" )} -> inbound | D158: =VLOOKUP(C158,$I$2:$J$5,2,FALSE) -> Block
... A1180: 158.247.210.58 | B1180: "APT43" | C1180: {=IFERROR( IF(SUMPRODUCT((LEN(B1180)-LEN(SUBSTITUTE(B1180,$F$2:$F$300,"")))*(($G$2:$G$300)="outbound"))>0,"outbound", IF(SUMPRODUCT((LEN(B1180)-LEN(SUBSTITUTE(B1180,$F$2:$F$300,"")))*(($G$2:$G$300)="inbound"))>0,"inbound","unknown")), "unknown" )} -> unknown | D1180: =VLOOKUP(C1180,$I$2:$J$5,2,FALSE) -> Alert
A1181: archibase.co | C1181: {=IFERROR( IF(SUMPRODUCT((LEN(B1181)-LEN(SUBSTITUTE(B1181,$F$2:$F$300,"")))*(($G$2:$G$300)="outbound"))>0,"outbound", IF(SUMPRODUCT((LEN(B1181)-LEN(SUBSTITUTE(B1181,$F$2:$F$300,"")))*(($G$2:$G$300)="inbound"))>0,"inbound","unknown")), "unknown" )} -> unknown | D1181: =VLOOKUP(C1181,$I$2:$J$5,2,FALSE) -> Alert
A1182: cardcpp.online | B1182: "MiningDropper" | C1182: {=IFERROR( IF(SUMPRODUCT((LEN(B1182)-LEN(SUBSTITUTE(B1182,$F$2:$F$300,"")))*(($G$2:$G$300)="outbound"))>0,"outbound", IF(SUMPRODUCT((LEN(B1182)-LEN(SUBSTITUTE(B1182,$F$2:$F$300,"")))*(($G$2:$G$300)="inbound"))>0,"inbound","unknown")), "unknown" )} -> unknown | D1182: =VLOOKUP(C1182,$I$2:$J$5,2,FALSE) -> Alert
A1183: whereisitat.lucyatemysuperbox.space | B1183: "Xinference", "supply chain attack" | C1183: {=IFERROR( IF(SUMPRODUCT((LEN(B1183)-LEN(SUBSTITUTE(B1183,$F$2:$F$300,"")))*(($G$2:$G$300)="outbound"))>0,"outbound", IF(SUMPRODUCT((LEN(B1183)-LEN(SUBSTITUTE(B1183,$F$2:$F$300,"")))*(($G$2:$G$300)="inbound"))>0,"inbound","unknown")), "unknown" )} -> unknown | D1183: =VLOOKUP(C1183,$I$2:$J$5,2,FALSE) -> Alert
A1184: 151.245.195.142 | B1184: "ClickFix", "cmdkey", "lolbins" | C1184: {=IFERROR( IF(SUMPRODUCT((LEN(B1184)-LEN(SUBSTITUTE(B1184,$F$2:$F$300,"")))*(($G$2:$G$300)="outbound"))>0,"outbound", IF(SUMPRODUCT((LEN(B1184)-LEN(SUBSTITUTE(B1184,$F$2:$F$300,"")))*(($G$2:$G$300)="inbound"))>0,"inbound","unknown")), "unknown" )} -> inbound | D1184: =VLOOKUP(C1184,$I$2:$J$5,2,FALSE) -> Block
A1185: nuevaprodeciencia.club | B1185: "agenteV2", "banking trojan" | C1185: {=IFERROR( IF(SUMPRODUCT((LEN(B1185)-LEN(SUBSTITUTE(B1185,$F$2:$F$300,"")))*(($G$2:$G$300)="outbound"))>0,"outbound", IF(SUMPRODUCT((LEN(B1185)-LEN(SUBSTITUTE(B1185,$F$2:$F$300,"")))*(($G$2:$G$300)="inbound"))>0,"inbound","unknown")), "unknown" )} -> unknown | D1185: =VLOOKUP(C1185,$I$2:$J$5,2,FALSE) -> Alert
A1186: 46.37.123.101 | B1186: "PhantomCore", "KermitRAT" | C1186: {=IFERROR( IF(SUMPRODUCT((LEN(B1186)-LEN(SUBSTITUTE(B1186,$F$2:$F$300,"")))*(($G$2:$G$300)="outbound"))>0,"outbound", IF(SUMPRODUCT((LEN(B1186)-LEN(SUBSTITUTE(B1186,$F$2:$F$300,"")))*(($G$2:$G$300)="inbound"))>0,"inbound","unknown")), "unknown" )} -> unknown | D1186: =VLOOKUP(C1186,$I$2:$J$5,2,FALSE) -> Alert
A1187: 2.59.153.146 | B1187: "Scanner" | C1187: {=IFERROR( IF(SUMPRODUCT((LEN(B1187)-LEN(SUBSTITUTE(B1187,$F$2:$F$300,"")))*(($G$2:$G$300)="outbound"))>0,"outbound", IF(SUMPRODUCT((LEN(B1187)-LEN(SUBSTITUTE(B1187,$F$2:$F$300,"")))*(($G$2:$G$300)="inbound"))>0,"inbound","unknown")), "unknown" )} -> inbound | D1187: =VLOOKUP(C1187,$I$2:$J$5,2,FALSE) -> Block
A1188: 2.59.153.95 | B1188: "Scanner" | C1188: {=IFERROR( IF(SUMPRODUCT((LEN(B1188)-LEN(SUBSTITUTE(B1188,$F$2:$F$300,"")))*(($G$2:$G$300)="outbound"))>0,"outbound", IF(SUMPRODUCT((LEN(B1188)-LEN(SUBSTITUTE(B1188,$F$2:$F$300,"")))*(($G$2:$G$300)="inbound"))>0,"inbound","unknown")), "unknown" )} -> inbound | D1188: =VLOOKUP(C1188,$I$2:$J$5,2,FALSE) -> Block
A1189: 2.59.153.210 | B1189: "Scanner" | C1189: {=IFERROR( IF(SUMPRODUCT((LEN(B1189)-LEN(SUBSTITUTE(B1189,$F$2:$F$300,"")))*(($G$2:$G$300)="outbound"))>0,"outbound", IF(SUMPRODUCT((LEN(B1189)-LEN(SUBSTITUTE(B1189,$F$2:$F$300,"")))*(($G$2:$G$300)="inbound"))>0,"inbound","unknown")), "unknown" )} -> inbound | D1189: =VLOOKUP(C1189,$I$2:$J$5,2,FALSE) -> Block
...

Sheet Legend
A1: Label | B1: Traffic (Outbound/Inbound/Unknown) | D1: Classification | E1: Follow up action
A2: 釣魚網站 | B2: outbound | D2: Inbound | E2: Block
A3: Websafe.Phishing | B3: outbound | D3: Outbound | E3: Block
A4: Phishing | B4: outbound | D4: Unknown | E4: Alert
A5: Silver fox | B5: unknown | D5: Direction Mismatch: Outbound/Inbound Conflict | E5: Alert
A6: OceanLotus | B6: unknown
A7: Generic Trojan | B7: unknown
A8: BlackMarket | B8: unknown
A9: Gh0st | B9: unknown
A10: SilverFox | B10: unknown
A11: Botnet | B11: outbound
A12: CnC | B12: outbound
A13: Scanner | B13: inbound
A14: CyberAttack | B14: unknown
A15: Spam | B15: inbound
A16: BruteForcer | B16: inbound
A17: Asyncrat | B17: unknown
... A146: 無 | B146: unknown

Sheet -> HKCPSA Raw Files

Sheet 惡意事件(A)
A1: HKCSPA_CTIWG_威脅情報_惡意事件_通報TISC
A2: 序號 | B2: 事件類型 | C2: 攻擊源類型 | D2: 攻擊源 | E2: 攻擊源運營商信息 | F2: 攻擊源威脅分析 （數據來源於網絡公開數據，僅供參考） | G2: 數據標籤 | H2: 惡意文件樣本 （文件名與文件指紋，數據來源於網絡公開數據，僅供參考） | I2: 提交機構
A3: 1 | B3: APT攻擊 | C3: ip | D3: 103.40.79.139 | E3: TELEGLOBAL COMMUNICATION SERVICES LIMITED（香港ISP） | F3: 1.該IP存在6個惡意的C段IP 2.該IP地址使用了可疑證書，可能被用於通訊加密躲避檢測 3.該IP地址近期有爆破IOT-HIKCAM、端口掃描等行為 4.該IP存在被蜜罐捕獲的記錄 | G3: 無 | H3: 無 | I3: HKCSI
A4: 2 | B4: APT攻擊 | C4: ip | D4: 14.29.236.229 | E4: Kamatera, Inc.（全球性‌雲服務提供商‌） | F4: 1.該IP地址的通信樣本中，絕大部分是Starter惡意軟件。說明該IP地址與Starter惡意軟件關系密切 2.該IP的反查域名包含惡意域名：pool.ubuntu-search.online，pool.ubuntu-search.xyz 3.該IP存在23個惡意的C段IP 4.該IP地址使用了可疑證書，可能被用於通訊加密躲避檢測 5.該IP曾被海蓮花團夥組織用於惡意攻擊行為 | G4: APT組織：OceanLotus | H4: 無 | I4: HKCSI
A5: 3 | B5: APT攻擊 | C5: ip | D5: 103.57.248.171 | E5: EDIS GmbH（奧地利ISP） | F5: 1.該IP的反查域名包含惡意域名：avic-cn.org 2.該IP存在2個惡意的C段IP | G5: 無 | H5: 無 | I5: HKCSI
A6: 4 | B6: APT攻擊 | C6: ip | D6: 138.199.62.10 | E6: Datacamp Limited（英國IT設備及網絡服務服務商） | F6: 1.該IP有暴力破解、主機劫持、DDoS攻擊2.該IP包含僵屍網絡節點特征 3.該IP存在13個惡意的C段IP 4.該IP地址使用了可疑證書，可能被用於通訊加密躲避檢測 5.該IP近期發起過漏洞利用行為，利用包括Nortek Linear eMerge E3-Series設備命令注入攻擊(CVE-2022-31499)，OGNL表達式注入攻擊，Adobe ColdFusion AMF遠程代碼執行攻擊(CVE-2023-29300)等漏洞 6.該IP存在被蜜罐捕獲的記錄 | G6: 無 | H6: fef909da671e01bc870fde9da9cdcc46：Linux.Trojan.Dropper.Kajl | I6: HKCSI
A7: 5 | B7: APT攻擊 | C7: ip | D7: 118.99.2.23 | E7: 科盈電信集團有限公司 | F7: 1.該IP包含僵屍網絡節點特征 2.該IP存在1個惡意的C段IP 3.該IP近期發起過漏洞利用行為，利用包括YouPHPTube命令注入攻擊(CVE-2019-5127)，DedeCMS SQL注入攻擊(CVE-2017-17731)，OGNL表達式注入攻擊等漏洞 4.該IP存在被蜜罐捕獲的記錄 | G7: 無 | H7: 無 | I7: HKCSI
A8: 6 | B8: APT攻擊 | C8: ip | D8: 149.40.54.75 | E8: CDN77（英國CDN服務提供商） | F8: 1.該IP存在3個惡意的C段IP 2.該IP地址為動態IP，可能被黑客用作遠控服務器 3.該IP近期發起過漏洞利用行為，利用包括SQL注入攻擊，泛微e-cology遠程命令執行攻擊，泛微e-cology SQL注入攻擊等漏洞 4.該IP被蜜罐捕獲過，屬於非定向攻擊者，有廣泛的攻擊目標 | G8: 無 | H8: 無 | I8: HKCSI
A9: 7 | B9: APT攻擊 | C9: ip | D9: 185.225.234.192 | E9: TerraTransit AG（德國ISP） | F9: 1.該IP包含僵屍網絡節點特征 2.該IP存在50個惡意的C段IP 3.該IP近期發起過漏洞利用行為，利用包括SQL注入攻擊等漏洞 4.該IP存在被蜜罐捕獲的記錄 | G9: 無 | H9: 無 | I9: HKCSI
A10: 8 | B10: APT攻擊 | C10: ip | D10: 185.225.234.62 | E10: TerraTransit AG（德國ISP） | F10: 1.包含僵屍網絡節點特征 2.該IP存在50個惡意的C段IP 3.該IP近期發起過漏洞利用行為包括用友NC bsh-servlet-BshServlet遠程命令執行攻擊，web-xml文件讀取攻擊，藍淩OA文件包含攻擊(CNVD-2021-28277)等 4.該IP存在被蜜罐捕獲的記錄 | G10: 無 | H10: 無 | I10: HKCSI
A11: 9 | B11: APT攻擊 | C11: ip | D11: 156.146.45.194 | E11: Datacamp Limited（英國IT設備及網絡服務服務商） | F11: 1.該IP存在25個惡意的C段IP 2.該IP近期發起過漏洞利用行為，利用包括ThinkPHP SQL注入攻擊，Web權限繞過攻擊，SQL注入攻擊等漏洞 3.該IP存在被蜜罐捕獲的記錄 | G11: 無 | H11: 無 | I11: HKCSI
A12: 10 | B12: APT攻擊 | C12: ip | D12: 185.225.234.144 | E12: TerraTransit AG（德國ISP） | F12: 1.該IP包含僵屍網絡節點特征 2.該IP存在49個惡意的C段IP 3.該IP近期發起過漏洞利用行為，包括遠程命令執行，Cockpit CMS NoSQL注入攻擊(CVE-2020-35846)，Apache拒絕服務攻擊(CVE-2012-3526)等漏洞 5.該IP存在被蜜罐捕獲的記錄 | G12: 無 | H12: 無 | I12: HKCSI
A13: 11 | B13: APT攻擊 | C13: ip | D13: 38.180.150.40 | E13: 3NT SOLUTIONS LLP（英國VPS服務商） | F13: 1.該IP地址使用了可疑證書，可能被用於通訊加密躲避檢測 | G13: APT組織：OceanLotus | H13: 無 | I13: HKCSI
A14: 12 | B14: APT攻擊 | C14: ip | D14: 183.87.124.189 | E14: 華為（香港公有雲服務商） | F14: 1.該IP存在11個惡意的C段IP 2.該IP地址為動態IP，可能被黑客用作遠控服務器 3.該IP地址近期有對外的端口掃描行為 4.該IP存在被蜜罐捕獲的記錄 | G14: 無 | H14: 無 | I14: HKCSI
... A24: 22 | B24: 僵屍木馬 | C24: ip | D24: 143.92.51.10 | E24: RACKIP CONSULTANCY PTE. LTD.（香港BGP線路運營商） | F24: 1.該IP存在255個惡意的C段IP | G24: 無 | H24: 03c3f5c2f6e50060057b0404da558610：Win32.Trojan.Cyclun.Fajl | I24: HKCSI
A25: 23 | B25: 僵屍木馬 | C25: ip | D25: 17.253.87.196 | E25: 蘋果公司 | F25: 1.該IP包含僵屍網絡節點特征 2.該IP地址有Apple Inc.頒發的有效證書，頒發給Apple Inc. 3.該IP地址近期有對外的端口掃描行為 | G25: 無 | I25: HKCSI
A26: 24 | B26: 僵屍木馬 | C26: ip | D26: 23.2.16.48 | E26: 阿卡邁（美國CDN服務提供商） | F26: 1.該IP存在1個惡意的C段IP 3.該IP地址近期有對外的端口掃描行為 4.該IP存在被蜜罐捕獲的記錄 | G26: 無 | H26: bc8984fefdb3931c214037ebc5a94d9a：Win32.Trojan.Inject.Sgil 368faf3e565f4c7f398225e719991226：Win32.Trojan.Jorik.Vimw 33c6b605e975a2910ce9c3cdd822f7f4：Win32.Trojan.Jorik.Ssmw c986342af7319980d32b10cd78e952c5：Win32.Trojan.Jorik.Twhl 9748acf159711317ce5cd85f39eb393b：Win32.Trojan.Jorik.Jcnw 等16個樣本 | I26: HKCSI
A27: 25 | B27: 僵屍木馬 | C27: ip | D27: 23.33.92.22 | E27: 阿卡邁（美國CDN服務提供商） | F27: 1.該IP包含僵屍網絡節點特征 2.該IP存在1個惡意的C段IP 3.該IP地址使用了可疑證書，可能被用於通訊加密躲避檢測 4.該IP地址近期有對外的端口掃描行為 5.該IP存在被蜜罐捕獲的記錄 | G27: 無 | H27: 4c8bd02ee339eb24aed1ce55d5ff85dc：Win32.AdWare.Adload.Xwhl acc889e3b0e8390270d9bf12de25e1dd：Win32.AdWare.Adload.Dzlw f7366551864aabd59673a06bfe4fcaa8：Win32.AdWare.Adload.Icnw b030baa32259d14910fd03c8803f877a：Win32.AdWare.Adload.Zfow 2d3845e0fd3bf86308d1b5148db59cf8：Win32.AdWare.Adload.Ddhl 等6個樣本 | I27: HKCSI
A28: 26 | B28: 僵屍木馬 | C28: ip | D28: 27.124.2.150 | E28: RACKIP CONSULTANCY PTE. LTD.（香港BGP線路運營商） | F28: 1.該IP地址與Suschil、Kryptik_AGen、Generic等惡意軟件有通信行為 2.該IP存在252個惡意的C段IP | G28: 惡意文件家族：Generic Trojan | H28: 39a5d58a2c55a97e784fb1caa14e35ec：Win32.Trojan.FalseSign.Hajl 917f01536b3ecf7205fc7bee39df9004：Win32.Trojan.Silverfox.Wmhl 5c5700ece4c6450f39204a183e5b51b3：Win32.Trojan.Silverfox.Vmhl 0ac9f2b4e20576608fa2908c589738a8：Win32.Trojan.Silverfox.Oqil 74ff5bc33f50041e702618b44a83468f：Win32.Trojan.Silverfox.Jqil 等8個樣本 | I28: HKCSI
A29: 27 | B29: 僵屍木馬 | C29: ip | D29: 43.152.24.67 | E29: 騰訊（香港公有雲服務商） | F29: 1.該IP有DDoS攻擊.該IP存在13個惡意的C段IP 3.該IP地址為動態IP，可能被黑客用作遠控服務器 4.該IP地址近期有對外的端口掃描行為 | G29: 無 | H29: 9d1d65b002c9f47e2628315b75f55bc9：Win32.Backdoor.Agent.Rsmw 77e4cdffc7bc3f27d91c5c624231f16f：Win32.Trojan.Generic.Cnhl 3a2a07fb9d15d68d6b294479fd581256：Win32.Trojan.Silverfox.Qgil 9230d634802feb96608cc1d31ce7512c：Win32.Trojan.Generic.Yolw 375e61f7d7919121ac906b1f6301ae5c：Win32.Trojan.Generic.Qsmw 等52個樣本 | I29: HKCSI
A30: 28 | B30: 僵屍木馬 | C30: ip | D30: 47.86.111.52 | E30: 阿裏雲（香港公有雲服務商） | F30: 1.該IP地址與灰色軟件LetsVPN等有通信行為，可能為灰產相關的IP地址 2.該IP的反查域名包含惡意域名：msthiyun.com，wentianskw168.com，wendalong168.com等 3.該IP地址使用了可疑證書，可能被用於通訊加密躲避檢測 | G30: 無 | H30: 2ae6454dcb7da2278b7330f5cd63f3ba：Win64.Backdoor.Phish-e.Ogil ee4106b808af37ef3381d035d4faeb7b：Win64.Backdoor.Phish-e.Gflw 92a7ece9cb406d15c3139fe1d181b0e2：Win32.Backdoor.Phish-e.Rsmw aa3311f399b7a10f1e3abd6fe0fc512c：Win32.Backdoor.Phish-e.Qsmw c777ae3fff97e19f483caffe806c8add：Win32.Backdoor.Phish-e.Kmnw 等54個樣本 | I30: HKCSI
A31: 29 | B31: 殭屍網絡感染 | C31: ip | D31: 149.104.0.145 | E31: XNNET LLC | G31: "BlackMarket", "Gh0st", "SilverFox", "Botnet" | I31: SSWK
A32: 30 | B32: 其他惡意事件 | C32: ip | D32: 192.238.180.148 | E32: Antbox Networks Limited | G32: "SilverFox", "CnC" | I32: SSWK
A33: 31 | B33: 其他惡意事件 | C33: ip | D33: 38.181.2.20 | E33: Hong Kong Communications International Co., Limited | G33: "SilverFox", "CnC" | I33: SSWK
A34: 32 | B34: 常規網絡攻擊 | C34: ip | D34: 143.92.32.165 | E34: CTG Server Limited | G34: "Scanner", "CyberAttack", "Spam", "Botnet", "BruteForcer" | I34: SSWK
A35: 33 | B35: 其他惡意事件 | C35: ip | D35: 202.79.174.192 | E35: CTG Server Limited | G35: "SilverFox", "CnC" | I35: SSWK
A36: 34 | B36: 殭屍網絡感染 | C36: ip | D36: 27.124.4.107 | E36: CTG Server Limited | G36: "Gh0st", "SilverFox", "Botnet" | I36: SSWK
A37: 35 | B37: 木馬感染 | C37: ip | D37: 47.83.225.15 | E37: Alibaba Cloud | G37: "Asyncrat", "Malware" | I37: SSWK
A38: 36 | B38: 其他惡意事件 | C38: ip | D38: 45.119.98.105 | E38: SonderCloud Limited | G38: "CnC" | I38: SSWK
A39: 37 | B39: 木馬感染 | C39: ip | D39: 154.38.113.14 | E39: Hong Kong Communications International Co., Limited | G39: "Malware", "SilverFox", "GoldenEyeDog" | I39: SSWK
A40: 38 | B40: 其他惡意事件 | C40: ip | D40: 47.86.111.52 | E40: Alibaba Cloud | G40: "SilverFox", "CnC" | I40: SSWK
A41: 39 | B41: 木馬感染 | C41: ip | D41: 27.124.43.226 | E41: CTG Server Limited | G41: "Malware", "GoldenEyeDog" | I41: SSWK
A42: 40 | B42: 木馬感染 | C42: ip | D42: 206.233.240.116 | E42: Zillion Network Inc. | G42: "Malware" | I42: SSWK
... A184: 182 | B184: 常規網絡攻擊 | C184: ip | D184: 223.17.47.129 | E184: HGC Global Communications Limited | G184: "Exploit", "CyberAttack", "Scanner" | I184: SSWK

Sheet 涉港釣魚網站專報
A1: HKCSPA_CTIWG_威脅情報_涉港釣魚網站專報_通報TISC
A2: 序號 | B2: 釣魚網站數據類型 | C2: 釣魚網站數據 | D2: 數據標籤 | E2: 提交機構
A3: 1 | B3: domain | C3: heeso.cis-edu.hk | D3: "釣魚網站", "Websafe.Phishing" | E3: 360
A4: 2 | B4: domain | C4: 00371.hk | D4: "釣魚網站", "Websafe.Phishing" | E4: 360
A5: 3 | B5: domain | C5: 2021.hk | D5: "釣魚網站", "Phishing" | E5: 360
A6: 4 | B6: domain | C6: 2021.hk | D6: "釣魚網站", "Phishing" | E6: 360
A7: 5 | B7: domain | C7: m3g3.hk | D7: "釣魚網站", "Websafe.Phishing" | E7: 360
A8: 6 | B8: domain | C8: zly.cis-edu.hk | D8: "釣魚網站", "Websafe.Phishing" | E8: 360
A9: 7 | B9: domain | C9: 798.hk | D9: "釣魚網站", "Websafe.Phishing" | E9: 360
A10: 8 | B10: domain | C10: pyd.cis-edu.hk | D10: "釣魚網站", "Websafe.Phishing" | E10: 360
A11: 9 | B11: domain | C11: 6uco6wrg.00489.hk | D11: "釣魚網站", "Websafe.Phishing" | E11: 360
A12: 10 | B12: domain | C12: aiqrta01.09626.hk | D12: "釣魚網站", "Websafe.Phishing" | E12: 360
A13: 11 | B13: domain | C13: ng.02328.hk | D13: "釣魚網站", "Websafe.Phishing" | E13: 360
A14: 12 | B14: domain | C14: vhy.hk | D14: "釣魚網站", "Websafe.Phishing" | E14: 360
... A402: 400 | B402: domain | C402: tdkf37.ime.hk | D402: "釣魚網站", "Silver fox" | E402: 360
B403: 數據支撐機構：360
B404: 數據整編機構：CTIWG技術支持團隊（香港網絡安全研究院）
B405: 數據問題溝通：ctiwg@hkcsi.hk

Sheet 惡意事件(B)
A1: HKCSPA_CTIWG_威脅情報_惡意事件_通報會員機構
A2: 序號 | B2: 事件類型 | C2: 攻擊源類型 | D2: 攻擊源 | E2: 攻擊源運營商 | F2: 攻擊目標類型 | G2: 攻擊目標 | H2: 攻擊目標運營商 | I2: 數據標籤 | J2: 提交機構
A3: 1 | B3: 掃描探測 | C3: ip | D3: 209.54.101.94 | I3: 掃描操作 | J3: HKCSI
A4: 2 | B4: 掃描探測 | C4: ip | D4: 213.209.159.233 | I4: TCP連接 | J4: HKCSI
A5: 3 | B5: 掃描探測 | C5: ip | D5: 45.148.10.49 | I5: TCP連接 | J5: HKCSI
A6: 4 | B6: 掃描探測 | C6: ip | D6: 209.38.240.240 | I6: 掃描操作 | J6: HKCSI
A7: 5 | B7: 掃描探測 | C7: ip | D7: 213.209.159.232 | I7: TCP連接 | J7: HKCSI
A8: 6 | B8: 掃描探測 | C8: ip | D8: 45.148.10.47 | I8: TCP連接 | J8: HKCSI
A9: 7 | B9: 掃描探測 | C9: ip | D9: 45.148.10.63 | I9: TCP連接 | J9: HKCSI
A10: 8 | B10: 掃描探測 | C10: ip | D10: 45.148.10.48 | I10: TCP連接 | J10: HKCSI
A11: 9 | B11: 掃描探測 | C11: ip | D11: 45.148.10.87 | I11: TCP連接 | J11: HKCSI
A12: 10 | B12: 掃描探測 | C12: ip | D12: 198.23.194.254 | I12: 掃描操作 | J12: HKCSI
A13: 11 | B13: 掃描探測 | C13: ip | D13: 154.23.238.16 | I13: 掃描操作 | J13: HKCSI
A14: 12 | B14: 掃描探測 | C14: ip | D14: 154.23.238.17 | I14: 掃描操作 | J14: HKCSI
... A535: 533 | B535: 掃描探測 | C535: ip | D535: 140.245.36.218 | I535: TCP轉發,TCP連接,HTTP訪問 | J535: HKCSI
A536: 534 | B536: 病毒感染 | C536: domain | D536: aomais.com | E536: The Constant Company, LLC | F536: ip | G536: 103.117.72.240 | H536: Zhengxing Technology | I536: "蠕蟲", "Pykspa" | J536: 360
A537: 535 | B537: 木馬感染 | C537: domain | D537: cwyfknmwh.biz | E537: SoftLayer Technologies Inc. | F537: ip | G537: 43.132.184.239 | H537: 騰訊 | I537: "木馬", "M0yv" | J537: 360
A538: 536 | B538: 木馬感染 | C538: domain | D538: unassigned.calpop.com | E538: GoDaddy.com, LLC | F538: ip | G538: 154.12.31.87 | H538: cognetcloud INC | I538: "木馬", "Trojangen" | J538: 360
A539: 537 | B539: 木馬感染 | C539: domain | D539: apple.vzboot.com | E539: Private Layer INC | F539: ip | G539: 103.73.160.198 | H539: cognetcloud INC | I539: "木馬", "Reconyc" | J539: 360
A540: 538 | B540: 木馬感染 | C540: domain | D540: o.0ye.pw | E540: 騰訊 | F540: ip | G540: 103.96.72.126 | H540: Cloudie Limited | I540: "木馬", "Generic" | J540: 360
A541: 539 | B541: 木馬感染 | C541: domain | D541: a.xulehe.abrdns.com | E541: PEG TECH INC | F541: ip | G541: 43.246.210.69 | H541: Hong Kong San Ai Net Int'l Limited | I541: "木馬", "Farfli" | J541: 360
A542: 540 | B542: 木馬感染 | C542: domain | D542: ai.microsoftgpt.net | E542: 阿裏雲 | F542: ip | G542: 203.12.200.250 | H542: 中國電信 | I542: "木馬", "Trojangen" | J542: 360
A543: 541 | B543: 木馬感染 | C543: domain | D543: bs.lastcode.xyz | E543: SonderCloud Limited | F543: ip | G543: 103.112.96.88 | H543: AROSSCLOUD INC. | I543: "木馬", "Rekoobe" | J543: 360
A544: 542 | B544: 木馬感染 | C544: domain | D544: viacolor.ind.br | E544: Skymail Serviços de Computação e Provimento de Inf | F544: ip | G544: 47.75.171.70 | H544: 阿裏雲 | I544: "木馬", "Trojangen" | J544: 360
A545: 543 | B545: 木馬感染 | C545: domain | D545: a.xulehe.abrdns.com | E545: PEG TECH INC | F545: ip | G545: 123.58.218.193 | H545: 優刻得信息科技（香港）有限公司 | I545: "木馬", "Farfli" | J545: 360
A546: 544 | B546: 挖礦軟件感染 | C546: domain | D546: donate.ssl.xmrig.com | E546: DigitalOcean, LLC | F546: ip | G546: 103.112.185.132 | H546: Cloudie Limited | I546: "挖礦事件", "Miningpool" | J546: 360
A547: 545 | B547: 挖礦軟件感染 | C547: domain | D547: pool-fr.supportxmr.com | E547: OVH SAS | F547: ip | G547: 147.161.32.140 | H547: 戴訊互聯有限公司 | I547: "挖礦事件", "XMRig" | J547: 360
... A555: 553 | B555: 挖礦軟件感染 | C555: domain | D555: donate.ssl.xmrig.com | E555: DigitalOcean, LLC | F555: ip | G555: 154.201.85.209 | H555: cognetcloud INC | I555: "挖礦事件", "Miningpool" | J555: 360
A556: 554 | B556: 木馬感染 | C556: domain | D556: cacgp.despacito5.com | F556: ip | G556: 8.218.153.243 | H556: 阿裏雲 | I556: "木馬", "Generic" | J556: 360
A557: 555 | B557: 木馬感染 | C557: domain | D557: cacgp.despacito5.com | F557: ip | G557: 8.210.77.229 | H557: 阿裏雲 | I557: "木馬", "Generic" | J557: 360
A558: 556 | B558: 挖礦軟件感染 | C558: domain | D558: supportxmr.com | E558: 阿卡邁 | F558: ip | G558: 45.114.125.90 | H558: HanMing HK Limited | I558: "挖礦事件", "BitCoinMiner" | J558: 360
A559: 557 | B559: 木馬感染 | C559: domain | D559: s1-i47p.5588888.xyz | E559: OVH SAS | F559: ip | G559: 103.106.189.173 | H559: cognetcloud INC | I559: "木馬", "Generic" | J559: 360
A560: 558 | B560: 挖礦軟件感染 | C560: domain | D560: supportxmr.com | E560: 阿卡邁 | F560: ip | G560: 103.242.3.71 | H560: Cloudie Limited | I560: "挖礦事件", "BitCoinMiner" | J560: 360
A561: 559 | B561: 木馬感染 | C561: domain | D561: jhvzpcfg.biz | E561: 亞馬遜 | F561: ip | G561: 43.132.184.239 | H561: 騰訊 | I561: "木馬", "Zegost" | J561: 360
A562: 560 | B562: 挖礦軟件感染 | C562: domain | D562: pool.hashvault.pro | E562: HIVELOCITY, Inc. | F562: ip | G562: 154.201.85.209 | H562: cognetcloud INC | I562: "挖礦事件", "BitCoinMiner" | J562: 360
A563: 561 | B563: 木馬感染 | C563: domain | D563: ssl.aaaaaaaa.cyou | E563: FASTNET DATA INC | F563: ip | G563: 103.73.163.240 | H563: cognetcloud INC | I563: "木馬", "Generic" | J563: 360
A564: 562 | B564: 挖礦軟件感染 | C564: domain | D564: coopmobil.cz | E564: O2 Czech Republic, a.s. | F564: ip | G564: 103.118.195.217 | H564: Cloudie Limited | I564: "挖礦事件", "Miner_general" | J564: 360
A565: 563 | B565: 木馬感染 | C565: domain | D565: 1.192-168-0-1.top | E565: Ansheng Network Technology Co., Limited | F565: ip | G565: 43.154.107.230 | H565: 騰訊 | I565: "木馬", "Generic" | J565: 360
A566: 564 | B566: 木馬感染 | C566: domain | D566: Kew.8dfabcdef.us | E566: 阿裏雲 | F566: ip | G566: 103.149.201.111 | H566: cognetcloud INC | I566: "木馬", "Generic" | J566: 360
A567: 565 | B567: 木馬感染 | C567: domain | D567: Kew.8dfabcdef.us | E567: 阿裏雲 | F567: ip | G567: 103.255.45.144 | H567: 網時集團有限公司 | I567: "木馬", "Generic" | J567: 360
...

Sheet DDoS攻擊
A1: HKCSPA_CTIWG_威脅情報_DDoS攻擊員機構
A2: 序號 | B2: 攻擊源 | C2: 數據標籤 | D2: 提交機構
A3: 1 | B3: 43.248.102.16 | C3: TCPSYN | D3: HKCSI
A4: 2 | B4: 146.56.45.136 | C4: TCPSYN | D4: HKCSI
A5: 3 | B5: 121.170.41.10 | C5: TCPSYN | D5: HKCSI
A6: 4 | B6: 160.176.0.220 | C6: TCPSYN | D6: HKCSI
A7: 5 | B7: 70.70.43.123 | C7: TCPSYN | D7: HKCSI
A8: 6 | B8: 211.62.183.142 | C8: TCPSYN | D8: HKCSI
A9: 7 | B9: 111.180.200.247 | C9: TCPSYN | D9: HKCSI
A10: 8 | B10: 1.158.83.130 | C10: TCPSYN | D10: HKCSI
A11: 9 | B11: 70.171.204.72 | C11: TCPSYN | D11: HKCSI
A12: 10 | B12: 58.6.205.96 | C12: TCPSYN | D12: HKCSI
A13: 11 | B13: 20.125.40.198 | C13: TCPSYN | D13: HKCSI
A14: 12 | B14: 124.184.134.198 | C14: TCPSYN | D14: HKCSI
... A503: 501 | B503: 45.249.247.111 | C503: "Application DDoS攻擊E-2008-3263" | D503: SSWK
A504: 502 | B504: 141.98.83.48 | D504: HQQY
A505: 503 | B505: 192.81.211.118 | D505: HQQY
A506: 504 | B506: 144.91.107.104 | D506: HQQY
A507: 505 | B507: 1.34.42.95 | D507: HQQY
A508: 506 | B508: 205.166.28.150 | D508: HQQY
A509: 507 | B509: 39.170.42.35 | D509: HQQY
A510: 508 | B510: 169.233.63.7 | D510: HQQY
A511: 509 | B511: 140.224.74.123 | D511: HQQY
A512: 510 | B512: 115.186.175.13 | D512: HQQY
A513: 511 | B513: 165.225.246.34 | D513: HQQY
A514: 512 | B514: 115.186.175.28 | D514: HQQY
A515: 513 | B515: 103.239.20.130 | D515: HQQY
... A540: 538 | B540: 203.184.192.225 | D540: HQQY

Sheet 釣魚網站
A1: HKCSPA_CTIWG_威脅情報_釣魚網站_通報會員機構
A2: 序號 | B2: 釣魚網站數據類型 | C2: 釣魚網站數據 | D2: 數據標籤 | E2: 提交機構
A3: 1 | B3: ip | C3: 136.232.184.134 | E3: HKCSI
A4: 2 | B4: ip | C4: 78.188.106.53 | E4: HKCSI
A5: 3 | B5: ip | C5: 147.45.47.64 | E5: HKCSI
A6: 4 | B6: ip | C6: 38.110.228.43 | E6: HKCSI
A7: 5 | B7: ip | C7: 37.187.161.206 | E7: HKCSI
A8: 6 | B8: ip | C8: 110.24.36.35 | E8: HKCSI
A9: 7 | B9: ip | C9: 70.166.207.76 | E9: HKCSI
A10: 8 | B10: ip | C10: 31.31.77.83 | E10: HKCSI
A11: 9 | B11: ip | C11: 216.126.225.148 | E11: HKCSI
A12: 10 | B12: ip | C12: 146.70.137.90 | E12: HKCSI
A13: 11 | B13: ip | C13: 201.196.15.79 | E13: HKCSI
A14: 12 | B14: ip | C14: 18.228.7.109 | E14: HKCSI
... A319: 317 | B319: url | C319: https://tt.grupobedfs.com/.../gera_pdf.php | E319: HKCSI
A320: 318 | B320: url | C320: http://www.bet6663.cc/ | D320: "Phishing" | E320: SSWK
A321: 319 | B321: url | C321: https://bet98d.com/ | D321: "Phishing" | E321: SSWK
A322: 320 | B322: url | C322: https://www.paris-bet365.com.cn/ | D322: "Phishing" | E322: SSWK
A323: 321 | B323: url | C323: https://oily-bet365.com.cn/ | D323: "Phishing" | E323: SSWK
A324: 322 | B324: url | C324: https://www.head-bet365.com.cn/ | D324: "Phishing" | E324: SSWK
A325: 323 | B325: url | C325: https://www.choice-bet365.com.cn/ | D325: "Phishing" | E325: SSWK
A326: 324 | B326: url | C326: https://h5.metamaskvip.top/ | D326: "Phishing" | E326: SSWK
A327: 325 | B327: url | C327: https://www.crispy-bet365.com.cn/ | D327: "Phishing" | E327: SSWK
A328: 326 | B328: url | C328: https://k69g.top/ | D328: "Phishing" | E328: SSWK
A329: 327 | B329: url | C329: https://syszgd.com/ | D329: "Phishing" | E329: SSWK
A330: 328 | B330: url | C330: https://zh-coinbase.com/ | D330: "Phishing" | E330: SSWK
A331: 329 | B331: url | C331: http://www.jsylcz.com/ | D331: "Phishing" | E331: SSWK
... A1571: 1569 | B1571: url | C1571: https://appustart-ledgr.wixstudio.com/en-us | D1571: "Phishing" | E1571: SSWK
A1572: 1570 | B1572: domain | C1572: sorvaweithirau.pics | E1572: TRX
A1573: 1571 | B1573: domain | C1573: taskformulate.com | E1573: TRX
A1574: 1572 | B1574: domain | C1574: studcake.online | E1574: TRX
A1575: 1573 | B1575: domain | C1575: streamhoukend.info | E1575: TRX
A1576: 1574 | B1576: domain | C1576: tradei6-duac.com | E1576: TRX
A1577: 1575 | B1577: domain | C1577: syriandentalassociation.net | E1577: TRX
A1578: 1576 | B1578: domain | C1578: trenttubi.net | E1578: TRX
A1579: 1577 | B1579: domain | C1579: thesaloddrria.cfd | E1579: TRX
A1580: 1578 | B1580: domain | C1580: tokenizer360-app.com | E1580: TRX
A1581: 1579 | B1581: domain | C1581: thebreakingnowpulse.pro | E1581: TRX
A1582: 1580 | B1582: domain | C1582: tekgrupmedya.net | E1582: TRX
A1583: 1581 | B1583: domain | C1583: theuajondia.lol | E1583: TRX
...

Sheet 專題-全球風險IP通報
A1: HKCSPA_CTIWG_威脅情報_專題-全球風險IP通報_通報會員機構
A2: 序號 | B2: IOC類型 | C2: IOC | D2: IP歸屬國家 | E2: IP歸屬地區 | F2: 惡意類別 | G2: 惡意家族名稱 | H2: 提交機構
A3: 1 | B3: ip | C3: 13.248.169.48 | D3: 美國 | E3: - | F3: 僵屍網絡 | G3: Mirai | H3: HKCSI
A4: 2 | B4: ip | C4: 64.62.203.98 | D4: 美國 | E4: 聖莫尼卡 | F4: 僵屍網絡 | G4: vo1d | H4: HKCSI
A5: 3 | B5: ip | C5: 64.62.203.97 | D5: 美國 | E5: 聖莫尼卡 | F5: 僵屍網絡 | G5: vo1d | H5: HKCSI
A6: 4 | B6: ip | C6: 103.224.182.217 | D6: 美國 | E6: 聖地亞哥 | F6: 僵屍網絡 | G6: vo1d | H6: HKCSI
A7: 5 | B7: ip | C7: 96.7.244.133 | D7: 日本 | E7: 東京 | F7: 僵屍網絡 | G7: 僵屍網絡 | H7: HKCSI
A8: 6 | B8: ip | C8: 169.2.1.1 | D8: 美國 | E8: 薩克拉門托 | F8: 僵屍網絡 | G8: 僵屍網絡 | H8: HKCSI
A9: 7 | B9: ip | C9: 45.144.172.15 | D9: 荷蘭 | E9: 霍爾勒 | F9: 僵屍網絡 | G9: 僵屍網絡 | H9: HKCSI
A10: 8 | B10: ip | C10: 37.120.210.219 | D10: 日本 | E10: 東京 | F10: 僵屍網絡 | G10: 僵屍網絡 | H10: HKCSI
A11: 9 | B11: ip | C11: 213.152.161.30 | D11: 荷蘭 | E11: 阿姆斯特丹 | F11: 僵屍網絡 | G11: 僵屍網絡 | H11: HKCSI
A12: 10 | B12: ip | C12: 185.156.174.155 | D12: 捷克 | E12: 布拉格 | F12: 僵屍網絡 | G12: 僵屍網絡 | H12: HKCSI
A13: 11 | B13: ip | C13: 134.122.154.247 | D13: 日本 | E13: 東京 | F13: 僵屍網絡 | G13: 下載者 | H13: HKCSI
A14: 12 | B14: ip | C14: 185.156.175.35 | D14: 瑞士 | E14: 蘇黎世 | F14: 僵屍網絡 | G14: 僵屍網絡 | H14: HKCSI
... A82: 80 | B82: domain | C82: ee.bsjdwn.com | D82: - | E82: - | F82: 遠控木馬 | G82: - | H82: HKCSI
A83: 81 | B83: domain | C83: stigp.sa.com | D83: - | E83: - | F83: 遠控木馬 | G83: -
A84: 82 | B84: domain | C84: 3qq.qcommerceshop.com | D84: - | E84: - | F84: 竊密木馬 | G84: -
A85: 83 | B85: domain | C85: oone8de.cn | D85: - | E85: - | F85: 遠控木馬 | G85: -
A86: 84 | B86: domain | C86: lestvvkpn.com | D86: - | E86: - | F86: 遠控木馬 | G86: -
A87: 85 | B87: domain | C87: sbido.com | D87: - | E87: - | F87: 遠控木馬 | G87: -
A88: 86 | B88: ip | C88: 199.247.29.25 | D88: 荷蘭 | E88: - | F88: APT | G88: 摩訶草
A89: 87 | B89: ip | C89: 194.87.108.94 | D89: 波蘭 | E89: - | F89: APT | G89: 海蓮花
A90: 88 | B90: ip | C90: 45.41.105.49 | D90: 緬甸 | E90: 仰光 | F90: 遠控木馬 | G90: -
A91: 89 | B91: ip | C91: 175.41.145.5 | D91: 新加坡 | E91: 新加坡 | F91: 僵屍網絡 | G91: -
A92: 90 | B92: ip | C92: 45.227.254.34 | D92: 立陶宛 | E92: 維爾紐斯 | F92: 漏洞利用 | G92: -
A93: 91 | B93: ip | C93: 31.3.152.100 | D93: 瑞典 | E93: 斯德哥爾摩 | F93: 僵屍網絡 | G93: -
A94: 92 | B94: ip | C94: 129.212.255.222 | D94: 美國 | E94: 森尼韋爾 | F94: 僵屍網絡 | G94: -
... A107: 105 | B107: domain | C107: dsguiwejbvysui.cn | D107: - | E107: - | F107: 遠控木馬 | G107: -
A108: 106 | B108: domain | C108: www.yyy16888.vip | D108: - | E108: - | F108: 遠控木馬
A109: 107 | B109: domain | C109: english-studies.net | D109: - | E109: - | F109: 遠控木馬 | G109: -
A110: 108 | B110: domain | C110: labelectechnology.com | D110: - | E110: - | F110: 遠控木馬 | G110: -
A111: 109 | B111: domain | C111: 2miners.com | D111: - | E111: - | F111: 挖礦木馬 | G111: -
A112: 110 | B112: domain | C112: truthink.in | D112: - | E112: - | F112: 遠控木馬 | G112: -
A113: 111 | B113: domain | C113: xiaoshihou40.org | D113: - | E113: - | F113: 遠控木馬 | G113: -
A114: 112 | B114: domain | C114: xiaoshihou37.org | D114: - | E114: - | F114: 遠控木馬 | G114: -
A115: 113 | B115: domain | C115: irusl.atlastimber.shop | D115: - | E115: - | F115: 遠控木馬 | G115: -
A116: 114 | B116: domain | C116: shunlissll.com | D116: - | E116: - | F116: 遠控木馬 | G116: -
A117: 115 | B117: domain | C117: shunshunlilixxsc.com | D117: - | E117: - | F117: 遠控木馬 | G117: -
A118: 116 | B118: domain | C118: ll.0z1zxmvo.com | D118: - | E118: - | F118: 遠控木馬 | G118: -
A119: 117 | B119: domain | C119: cdn.openroute.dev | D119: - | E119: - | F119: 遠控木馬 | G119: -
...

Sheet 涉香港金融行業釣魚網站
A1: 涉香港金融行業釣魚網站
A2: 序號 | B2: 釣魚網站URL | C2: 涉及目標 | D2: 提交機構
A3: 1 | B3: mabanquereunion.bnpparibas/ | C3: 金融機構 | D3: WBZX
A4: 2 | B4: d318d6p1c4tjb9.cloudfront.net/h5/#/login | C4: 金融機構 | D4: WBZX
A5: 3 | B5: ht717.ensemble98.top/h5/#/login | C5: 金融機構 | D5: WBZX
A6: 4 | B6: hui.pvkkp29.cn/#/pages/login/login | C6: 金融機構 | D6: WBZX
A7: 5 | B7: wap.ouboo.top/%E6%AC%A2%E8%BF%8E%E4%BD%BF%E7%94%A8_files/welcome.html | C7: 金融機構 | D7: WBZX
A8: 6 | B8: flux.ouboo.top/%E6%AC%A2%E8%BF%8E%E4%BD%BF%E7%94%A8_files/welcome.html | C8: 金融機構 | D8: WBZX
A9: 7 | B9: 156.247.41.16/%E6%AC%A2%E8%BF%8E%E4%BD%BF%E7%94%A8_files/welcome.html | C9: 金融機構 | D9: WBZX
A10: 8 | B10: dh.ouboo.top/%E6%AC%A2%E8%BF%8E%E4%BD%BF%E7%94%A8_files/welcome.html | C10: 金融機構 | D10: WBZX
A11: 9 | B11: hshcgold.com/%E6%AC%A2%E8%BF%8E%E4%BD%BF%E7%94%A8_files/welcome.html | C11: 金融機構 | D11: WBZX
A12: 10 | B12: 31.57.51.16/%E6%AC%A2%E8%BF%8E%E4%BD%BF%E7%94%A8_files/welcome.html | C12: 金融機構 | D12: WBZX
A13: 11 | B13: presse.realestate.bnpparibas.fr/ | C13: 金融機構 | D13: WBZX
A14: 12 | B14: 43.198.203.201/login | C14: 金融機構 | D14: WBZX
... A90: 88 | B90: hfvip.net/login | C90: 金融機構 | D90: WBZX
